<?xml version="1.0" ?>
<!-- =================================================================================== -->
<!-- |    This document was autogenerated by xacro from /home/xybxy/w_work/catkin_ws/src/RC2026/arm_model/urdf/arm_simple.xacro | -->
<!-- |    EDITING THIS FILE BY HAND IS NOT RECOMMENDED                                 | -->
<!-- =================================================================================== -->
<robot name="simple_arm_3link">
    <link name="world" />
    <material name="blue">
        <color rgba="0 0 0.8 1" />
    </material>
    <material name="gray">
        <color rgba="0.7 0.7 0.7 1" />
    </material>
    <material name="red">
        <color rgba="0.8 0 0 1" />
    </material>
    <!-- 添加绿色材料用于第三连杆 -->
    <material name="green">
        <color rgba="0 0.8 0 1" />
    </material>
    <!-- 添加黄色材料用于末端小球 -->
    <material name="yellow">
        <color rgba="0.8 0.8 0 1" />
    </material>
    <link name="base_link">
        <inertial>
            <mass value="1.0" />
            <origin xyz="0 0 0" rpy="0 0 0" />
            <inertia ixx="0.0" ixy="0" ixz="0" iyy="0.0" iyz="0" izz="0.0" />
        </inertial>
        <visual>
            <geometry>
                <cylinder length="0.0" radius="0.0" />
            </geometry>
            <material name="gray" />
        </visual>
        <collision>
            <geometry>
                <cylinder length="0.0" radius="0.0" />
            </geometry>
        </collision>
    </link>
    <joint name="world_to_base_fixed" type="fixed">
        <parent link="world" />
        <child link="base_link" />
        <origin rpy="0 0 0" xyz="0 0 0.0" />
    </joint>
    <link name="turret_link">
        <inertial>
            <mass value="0.5" />
            <origin xyz="0 0 0" rpy="0 0 0" />
            <inertia ixx="0.0" ixy="0" ixz="0" iyy="0.0" iyz="0" izz="0.0" />
        </inertial>
        <visual name="turret_blue_part">
            <origin xyz="0 0 -0.0" />
            <geometry>
                <cylinder length="0.0" radius="0.0" />
            </geometry>
            <material name="blue" />
        </visual>
        <visual name="turret_red_part">
            <origin xyz="0 0 0.0" />
            <geometry>
                <cylinder length="0.0" radius="0.0" />
            </geometry>
            <material name="red" />
        </visual>
        <collision>
            <geometry>
                <cylinder length="0.0" radius="0.0" />
            </geometry>
        </collision>
    </link>
    <joint name="base_to_turret" type="revolute">
        <parent link="base_link" />
        <child link="turret_link" />
        <origin rpy="0 0 0" xyz="0 0 0.0" />
        <axis xyz="0 0 1" />
        <limit effort="20" lower="-3.14" upper="3.14" velocity="1.0" />
        <dynamics damping="1.0" friction="0.1" />
    </joint>
    <gazebo joint="base_to_turret">
        <hardwareInterface>hardware_interface/PositionJointInterface</hardwareInterface>
        <plugin name="gazebo_ros_control" filename="libgazebo_ros_control.so">
            <robotNamespace>/</robotNamespace>
        </plugin>
    </gazebo>
    <transmission name="base_to_turret_trans">
        <type>transmission_interface/SimpleTransmission</type>
        <joint name="base_to_turret">
            <hardwareInterface>hardware_interface/PositionJointInterface</hardwareInterface>
        </joint>
        <actuator name="base_to_turret_motor">
            <hardwareInterface>hardware_interface/PositionJointInterface</hardwareInterface>
            <mechanicalReduction>1</mechanicalReduction>
        </actuator>
    </transmission>
    <!-- 第一连杆 -->
    <link name="first_arm_link">
        <inertial>
            <mass value="0.5" />
            <origin xyz="0 0 0.1721" rpy="0 0 0" />
            <!-- 重心在连杆中心 -->
            <inertia ixx="0.005048901666666666" ixy="0" ixz="0" iyy="0.005048901666666666" iyz="0" izz="0.000225" />
        </inertial>
        <visual>
            <origin xyz="0 0 0.1721" />
            <!-- 圆柱体中心在连杆中心 -->
            <geometry>
                <cylinder length="0.3442" radius="0.03" />
            </geometry>
            <material name="blue" />
        </visual>
        <collision>
            <origin xyz="0 0 0.1721" />
            <!-- 碰撞体中心也在连杆中心 -->
            <geometry>
                <cylinder length="0.3442" radius="0.03" />
            </geometry>
        </collision>
    </link>
    <!-- 第一连杆关节：位于云台上表面，第一连杆下表面与云台上表面连接 -->
    <joint name="turret_to_first_arm" type="revolute">
        <parent link="turret_link" />
        <child link="first_arm_link" />
        <!-- 关节位于云台上表面，第一连杆下表面与云台上表面连接 -->
        <origin rpy="0 0 0" xyz="0 0 0.0" />
        <axis xyz="0 1 0" />
        <limit effort="20" lower="-1.57" upper="1.57" velocity="1.0" />
        <dynamics damping="1.0" friction="0.1" />
    </joint>
    <gazebo joint="turret_to_first_arm">
        <hardwareInterface>hardware_interface/PositionJointInterface</hardwareInterface>
    </gazebo>
    <transmission name="turret_to_first_arm_trans">
        <type>transmission_interface/SimpleTransmission</type>
        <joint name="turret_to_first_arm">
            <hardwareInterface>hardware_interface/PositionJointInterface</hardwareInterface>
        </joint>
        <actuator name="turret_to_first_arm_motor">
            <hardwareInterface>hardware_interface/PositionJointInterface</hardwareInterface>
            <mechanicalReduction>1</mechanicalReduction>
        </actuator>
    </transmission>
    <!-- 第二连杆 -->
    <link name="second_arm_link">
        <inertial>
            <mass value="0.5" />
            <origin xyz="0 0 0.20738" rpy="0 0 0" />
            <!-- 重心在连杆中心 -->
            <inertia ixx="0.007280244066666668" ixy="0" ixz="0" iyy="0.007280244066666668" iyz="0" izz="0.000225" />
        </inertial>
        <visual>
            <origin xyz="0 0 0.20738" />
            <!-- 圆柱体中心在连杆中心 -->
            <geometry>
                <cylinder length="0.41476" radius="0.03" />
            </geometry>
            <material name="blue" />
        </visual>
        <collision>
            <origin xyz="0 0 0.20738" />
            <!-- 碰撞体中心也在连杆中心 -->
            <geometry>
                <cylinder length="0.41476" radius="0.03" />
            </geometry>
        </collision>
    </link>
    <!-- 第二连杆关节：位于第一连杆上表面，第二连杆下表面与第一连杆上表面连接 -->
    <joint name="first_to_second_arm" type="revolute">
        <parent link="first_arm_link" />
        <child link="second_arm_link" />
        <!-- 关节位于第一连杆上表面 -->
        <origin rpy="0 0 0" xyz="0 0 0.3442" />
        <axis xyz="0 1 0" />
        <limit effort="20" lower="-3.14" upper="3.14" velocity="1.0" />
        <dynamics damping="1.0" friction="0.1" />
    </joint>
    <gazebo joint="first_to_second_arm">
        <hardwareInterface>hardware_interface/PositionJointInterface</hardwareInterface>
    </gazebo>
    <transmission name="first_to_second_arm_trans">
        <type>transmission_interface/SimpleTransmission</type>
        <joint name="first_to_second_arm">
            <hardwareInterface>hardware_interface/PositionJointInterface</hardwareInterface>
        </joint>
        <actuator name="first_to_second_arm_motor">
            <hardwareInterface>hardware_interface/PositionJointInterface</hardwareInterface>
            <mechanicalReduction>1</mechanicalReduction>
        </actuator>
    </transmission>
    <!-- 第三连杆 -->
    <link name="third_arm_link">
        <inertial>
            <mass value="0.3" />
            <origin xyz="0 0 0.06675" rpy="0 0 0" />
            <!-- 重心在连杆中心 -->
            <inertia ixx="0.00051305625" ixy="0" ixz="0" iyy="0.00051305625" iyz="0" izz="0.000135" />
        </inertial>
        <visual>
            <origin xyz="0 0 0.06675" />
            <!-- 圆柱体中心在连杆中心 -->
            <geometry>
                <cylinder length="0.1335" radius="0.03" />
            </geometry>
            <material name="green" />
        </visual>
        <collision>
            <origin xyz="0 0 0.06675" />
            <!-- 碰撞体中心也在连杆中心 -->
            <geometry>
                <cylinder length="0.1335" radius="0.03" />
            </geometry>
        </collision>
    </link>
    <!-- 第三连杆关节：位于第二连杆上表面，第三连杆下表面与第二连杆上表面连接 -->
    <joint name="second_to_third_arm" type="revolute">
        <parent link="second_arm_link" />
        <child link="third_arm_link" />
        <!-- 关节位于第二连杆上表面 -->
        <origin rpy="0 0 0" xyz="0 0 0.41476" />
        <axis xyz="0 1 0" />
        <limit effort="20" lower="-3.14" upper="3.14" velocity="1.0" />
        <dynamics damping="1.0" friction="0.1" />
    </joint>
    <gazebo joint="second_to_third_arm">
        <hardwareInterface>hardware_interface/PositionJointInterface</hardwareInterface>
    </gazebo>
    <transmission name="second_to_third_arm_trans">
        <type>transmission_interface/SimpleTransmission</type>
        <joint name="second_to_third_arm">
            <hardwareInterface>hardware_interface/PositionJointInterface</hardwareInterface>
        </joint>
        <actuator name="second_to_third_arm_motor">
            <hardwareInterface>hardware_interface/PositionJointInterface</hardwareInterface>
            <mechanicalReduction>1</mechanicalReduction>
        </actuator>
    </transmission>
    <!-- 末端小球链接 -->
    <link name="end_effector_link">
        <inertial>
            <mass value="0.001" />
            <origin xyz="0 0 0" rpy="0 0 0" />
            <!-- 球体的惯性矩阵 -->
            <inertia ixx="4e-10" ixy="0" ixz="0" iyy="4e-10" iyz="0" izz="4e-10" />
        </inertial>
        <visual>
            <geometry>
                <sphere radius="0.001" />
            </geometry>
            <material name="yellow" />
        </visual>
        <collision>
            <geometry>
                <sphere radius="0.001" />
            </geometry>
        </collision>
    </link>
    <!-- 末端小球关节：固定关节连接到第三连杆末端 -->
    <joint name="third_arm_to_end_effector" type="fixed">
        <parent link="third_arm_link" />
        <child link="end_effector_link" />
        <!-- 关节位于第三连杆末端 -->
        <origin rpy="0 0 0" xyz="0 0 0.1335" />
    </joint>
    <gazebo>
        <plugin filename="libgazebo_ros_control.so" name="gazebo_ros_control">
            <robotNamespace>/</robotNamespace>
            <robotSimType>gazebo_ros_control/DefaultRobotHWSim</robotSimType>
        </plugin>
    </gazebo>
</robot>

